Workbook
Name a: '[2]区間回線名情報 (2)'!#REF!
Name i: #REF!

Sheet Layout MH
A1: Tên system | K1: Loại system | W1: =IF([3]Bìa!W1="","",[3]Bìa!W1) -> TKCB | AZ1: Người tạo | BD1: Ngày tạo | BI1: Người update | BM1: Ngày update | BR1: Version
A2: =IF([3]Bìa!A2="","",[3]Bìa!A2) -> Manage User | K2: =IF([3]Bìa!K2="","",[3]Bìa!K2) -> Thiết kế màn hình | AZ2: =IF([3]Bìa!AP2="","",[3]Bìa!AP2) -> LongLD | BD2: =IF([3]Bìa!AT2="","",[3]Bìa!AT2) -> 45078 | BI2: =IF([3]Bìa!AY2="","",[3]Bìa!AY2) -> LongLD | BM2: =IF([3]Bìa!BC2="","",[3]Bìa!BC2) -> 45078 | BR2: =IF([3]Bìa!BH2="","",[3]Bìa!BH2) -> 0.1
A4: Category chức năng | H4: =IF([3]Bìa!H4="","",[3]Bìa!H4) | U4: Hạng mục | Z4: =IF([3]Bìa!Z4="","",[3]Bìa!Z4) | AZ4: Layout MH
B6: ■ Nhân viên > List nhân viên (ADM002)
AZ7: Màn hình list nhân viên
BA9: URL vào là http(s)://ip_address/user/list
BA11: Có các chức năng chính
BB12: Search: search all và điều kiện (có sort)
BB13: Add: Link đến màn hình add mới ADM004
BB14: Sort: sort theo các trường
BC15: 氏名 (name)
BC16: 日本語能力 (trình độ JP)
BC17: 失効日 (ngày chứng chỉ JP hết hạn)
BB18: Chi tiết: Link đến màn hình chi tiết ADM003
BB19: Paging: Phân trang, mỗi page 20 bản ghi

Sheet Định nghĩa hạng mục
A1: Tên system | K1: Loại system | W1: =IF([3]Bìa!W1="","",[3]Bìa!W1) -> TKCB | AT1: Người tạo | AX1: Ngày tạo | BC1: Người update | BG1: Ngày update | BL1: Version
A2: =IF([3]Bìa!A2="","",[3]Bìa!A2) -> Manage User | K2: =IF([3]Bìa!K2="","",[3]Bìa!K2) -> Thiết kế màn hình | AT2: =IF([3]Bìa!AP2="","",[3]Bìa!AP2) -> LongLD | AX2: =IF([3]Bìa!AT2="","",[3]Bìa!AT2) -> 45078 | BC2: =IF([3]Bìa!AY2="","",[3]Bìa!AY2) -> LongLD | BG2: =IF([3]Bìa!BC2="","",[3]Bìa!BC2) -> 45078 | BL2: =IF([3]Bìa!BH2="","",[3]Bìa!BH2) -> 0.1
A4: Category chức năng | H4: =IF([3]Bìa!H4="","",[3]Bìa!H4) | U4: Hạng mục | Z4: =IF([3]Bìa!Z4="","",[3]Bìa!Z4) | AT4: Định nghĩa hạng mục
B6: ■ Nhân viên > List nhân viên (ADM002)
B7: No | D7: Tên hạng mục | M7: I/O | O7: Bắt buộc | Q7: Loại control | V7: Type | Z7: Min ký tự | AB7: Max ký tự | AD7: Format | AH7: Mapping hạng mục | AX7: Note
AH8: API tham chiếu | AN8: Trường tham chiếu
B9: 1 | D9: Logo | M9: O | O9: － | Q9: Image | V9: － | AX9: Logo công ty + text tên cty: Luvina Software
B10: 2 | D10: Sign out | M10: O | O10: － | Q10: Link | V10: － | AX10: Clear storage, chuyển sang màn hình login ADM001
B11: 3 | D11: Top | M11: O | O11: － | Q11: Link | V11: － | AX11: Khi user click vào link scroll MH lên top
B12: 4 | D12: Title | M12: O | O12: － | Q12: Label | V12: － | AX12: Text cố định
B13: 5 | D13: Title hạng mục search Fullname | M13: O | O13: － | Q13: Label | V13: － | AX13: Text cố định
B14: 6 | D14: Điều kiện search Fullname | M14: I | O14: － | Q14: Text | V14: － | Z14: 0 | AB14: 125 | AX14: Nếu fullname là rỗng thì ko search fullname, ngược lại điều kiện search là mapping một phần( LIKE %Fullname%) Trên MH nhập fix cố định cho phép user chỉ nhập tối đa 125 kí tự
B15: 7 | D15: Title hạng mục search Department | M15: O | O15: － | Q15: Label | V15: － | AX15: Text cố định
B16: 8 | D16: Điều kiện search Department | M16: I | O16: － | Q16: Dropdown List | V16: － | AH16: API List departments | AN16: giá trị là department id label là department name | AX16: Dropdown giá trị là danh sách phòng ban Cho phép chọn rỗng (phần tử đầu là rỗng). Nêú user chọn rỗng thì ko search department, ngược lại search theo department id
B17: 9 | D17: Button Search | M17: － | O17: － | Q17: Button | V17: － | AX17: Thực hiện search (gọi API List employees) theo điều kiện search
B18: 10 | D18: Button Add mới | M18: － | O18: － | Q18: Button | V18: － | AX18: chuyển sang màn hình add mới ADM004
B19: 11 | D19: Header Bảng danh sách nhân viên | M19: O | Q19: Label | V19: － | AX19: Có các cột: ID, 氏名, 生年月日, グループ,メールアドレス,電話番号,日本語能力, 失効日, 点数. Trong đó: các cột 氏名, 日本語能力, 失効日 có biểu tượng sort, khi click vào toàn bộ title của cột thì thực hiện sort tại server (gọi API),mặc định ban đầu tất cả đều sort theo asc (biểu tượng ▲▽), khi click vào cột nào thì sort đảo ngược trạng thái sort hiện tại. Ví dụ: trạng thái cột đang là asc (▲▽), click vào title thì chuyển thành desc (▼△) và gọi API để sort. Click tiếp thì đang là desc (▼△) chuyển thành (▲▽) và gọi API List employees để sort tiếp
B20: 12 | D20: Danh sách ID nhân viên | M20: O | O20: － | Q20: Link | V20: － | AX20: Hiển thị danh sách ID nhân viên lấy từ API Click vào từng ID sẽ gọi API Get Employee và chuyển sang màn hình view chi tiết nhân viên ADM003
B21: 13 | D21: Danh sách tên nhân viên | M21: O | O21: － | Q21: Label | V21: － | AX21: Hiển thị danh sách tên nhân viên tương ứng với từng ID lấy từ API
B22: 14 | D22: Danh sách ngày sinh nhân viên | M22: O | O22: － | Q22: Label | V22: － | AX22: Hiển thi danh sách ngày sinh nhân viên tương ứng với từng ID lấy từ API
B23: 15 | D23: Danh sách phòng ban nhân viên | M23: O | O23: － | Q23: Label | V23: － | AX23: Hiển thi danh sách phòng ban nhân viên tương ứng với từng ID lấy từ API
B24: 16 | D24: Danh sách email nhân viên | M24: O | O24: － | Q24: Label | V24: － | AX24: Hiển thi danh sách email nhân viên tương ứng với từng ID lấy từ API
B25: 17 | D25: Danh sách số điện thoại nhân viên | M25: O | O25: － | Q25: Label | V25: － | AX25: Hiển thi danh sách Số điện thoại nhân viên tương ứng với từng ID lấy từ API
B26: 18 | D26: Danh sách chứng chỉ JP nhân viên | M26: O | O26: － | Q26: Label | V26: － | AX26: Hiển thi danh sách chứng chỉ JP nhân viên tương ứng với từng ID lấy từ API
B27: 19 | D27: Danh sách ngày hết han chứng chỉ JP nhân viên | M27: O | O27: － | Q27: Label | V27: － | AX27: Hiển thi danh sách ngày hết hạn chứng chỉ JP nhân viên tương ứng với từng ID lấy từ API
B28: 20 | D28: Danh sách điểm thi chứng chỉ JP nhân viên | M28: O | O28: － | Q28: Label | V28: － | AX28: Hiển thi danh sách điểm thi chứng chỉ JP nhân viên tương ứng với từng ID lấy từ API
B29: 21 | D29: Phân trang | M29: － | O29: － | Q29: Button | AX29: Button phân trang
B30: 22 | D30: Footer | M30: O | O30: － | Q30: Label | AX30: Text cố định

Sheet Chi tiết xử lý
A1: Tên system | K1: Loại system | W1: =IF([3]Bìa!W1="","",[3]Bìa!W1) -> TKCB | AP1: Người tạo | AT1: Ngày tạo | AY1: Người update | BC1: Ngày update | BH1: Version
A2: =IF([3]Bìa!A2="","",[3]Bìa!A2) -> Manage User | K2: =IF([3]Bìa!K2="","",[3]Bìa!K2) -> Thiết kế màn hình | AP2: =IF([3]Bìa!AP2="","",[3]Bìa!AP2) -> LongLD | AT2: =IF([3]Bìa!AT2="","",[3]Bìa!AT2) -> 45078 | AY2: =IF([3]Bìa!AY2="","",[3]Bìa!AY2) -> LongLD | BC2: =IF([3]Bìa!BC2="","",[3]Bìa!BC2) -> 45078 | BH2: =IF([3]Bìa!BH2="","",[3]Bìa!BH2) -> 0.1
A4: Category chức năng | H4: =IF([3]Bìa!H4="","",[3]Bìa!H4) | U4: Hạng mục | Z4: =IF([3]Bìa!Z4="","",[3]Bìa!Z4) | AP4: Chi tiết xử lý
B7: I. Xử lý common
C8: Phần header: (tất cả các màn hình, trừ màn hình login)
D9: Logout:
E10: Clear session storage, di chuyển về màn hình login
D12: Top
E13: Thực hiện scroll lên top
C15: Lỗi gọi API
D16: Khi gọi API mà server trả về HTTP status code
E17: 5xx: redirect sang màn hình System error
E18: 401, 403: redirect sang màn hình Login
E19: Các lỗi khác thông báo tại màn hình
C21: Lỗi truy cập URL không tồn tại
D22: Khi user cố tình truy cập vào URL ko tồn tại, redirect sang màn hình System error với message "Page not found" (ER022)
C24: Lỗi bất thường xảy ra
D25: Redirect sang màn hình System error với message "System Error" (ER023)
C27: Hạng mục nhập date
D28: Hạng mục nhập date gồm textbox và icon calendar
D29: Trong đó textbox ko cho phép nhập trực tiếp bằng keyboard (disable)
D30: Muốn nhập user phải click chọn calendar từ icon calendar để mở popup calendar như hình dưới,
D31: User chọn 1 date từ popup calendar thì fill text vào textbox (định dạng yyyy/MM/dd)
E47: Khi cần disable thì ko cho click từ icon calendar
C49: Validate
D50: Tất cả các hạng mục nhập yêu cầu validate thì thực hiện validate ngay khi user tương tác với control
D51: Với các hạng mục có lỗi thì trên UI hightlight hạng mục đó (tô màu border thành màu đỏ), khi không có lỗi thì để như ban đầu (giống mock)
D52: Khi hạng mục lỗi, message lỗi hiển thị ngay dưới hạng mục, tô màu đỏ, khi ko có lỗi thì clear message lỗi
D53: Với các lỗi chung ko liên quan đến hạng mục như server trả về lỗi, gọi API ko thành công,... hiển thị message lỗi ngay dưới header của page (tô màu đỏ)
D54: Các hạng mục bắt buộc nhập hiển thị kí hiệu (*) màu đỏ ngay sau tiêu đề hạng mục (nếu hạng mục có tiêu đề)
C56: Focus và tab index
D57: Với các màn hình nhập: khi mới vào lần đầu, focus con trỏ vào hạng mục nhập đầu tiên
D58: Các hạng mục để tab index theo thứ tự từ trái qua phải, từ trên xuống dưới
C60: Dropdown:
D61: Tất cả các dropdown nếu ko đề cập gì đều có phần tử rỗng ở đầu
C63: Phân trang
D64: Hiển thị
E65: Luôn hiển thị button trang đầu tiên và trang cuối cùng. Nếu tổng số trang = 1 thì không hiển thị phần phân trang
E66: Hiển thị button trang hiện tại, kèm button trang ngay trước và trang ngay sau của trang hiện tại
G67: Ví dụ nếu đang ở trang 5, tổng số trang là 15 thì hiển thị như sau < 1 … 4 5 6 … 15 >
...

Sheet Flow xử lý
A1: Tên system | K1: Loại system | W1: =IF([3]Bìa!W1="","",[3]Bìa!W1) -> TKCB | AP1: Người tạo | AT1: Ngày tạo | AY1: Người update | BC1: Ngày update | BH1: Version
A2: =IF([3]Bìa!A2="","",[3]Bìa!A2) -> Manage User | K2: =IF([3]Bìa!K2="","",[3]Bìa!K2) -> Thiết kế màn hình | AP2: =IF([3]Bìa!AP2="","",[3]Bìa!AP2) -> LongLD | AT2: =IF([3]Bìa!AT2="","",[3]Bìa!AT2) -> 45078 | AY2: =IF([3]Bìa!AY2="","",[3]Bìa!AY2) -> LongLD | BC2: =IF([3]Bìa!BC2="","",[3]Bìa!BC2) -> 45078 | BH2: =IF([3]Bìa!BH2="","",[3]Bìa!BH2) -> 0.1
A4: Category chức năng | H4: =IF([3]Bìa!H4="","",[3]Bìa!H4) | U4: Hạng mục | Z4: =IF([3]Bìa!Z4="","",[3]Bìa!Z4) | AP4: Flow xử lý
B7: ■Xử lý hiển thị search list nhân viên

Sheet API sử dụng
A1: Tên system | K1: Loại system | W1: =IF([3]Bìa!W1="","",[3]Bìa!W1) -> TKCB | AP1: Người tạo | AT1: Ngày tạo | AY1: Người update | BC1: Ngày update | BH1: Version
A2: =IF([3]Bìa!A2="","",[3]Bìa!A2) -> Manage User | K2: =IF([3]Bìa!K2="","",[3]Bìa!K2) -> Thiết kế màn hình | AP2: =IF([3]Bìa!AP2="","",[3]Bìa!AP2) -> LongLD | AT2: =IF([3]Bìa!AT2="","",[3]Bìa!AT2) -> 45078 | AY2: =IF([3]Bìa!AY2="","",[3]Bìa!AY2) -> LongLD | BC2: =IF([3]Bìa!BC2="","",[3]Bìa!BC2) -> 45078 | BH2: =IF([3]Bìa!BH2="","",[3]Bìa!BH2) -> 0.1
A4: Category chức năng | H4: =IF([3]Bìa!H4="","",[3]Bìa!H4) | U4: Hạng mục | Z4: =IF([3]Bìa!Z4="","",[3]Bìa!Z4) | AP4: API sử dụng
B7: ■Danh sách API sử dụng
D9: No. | F9: Tên service | P9: Tên vật lý | AF9: Phương thức | AL9: File tham chiếu
D10: 2 | F10: List departments | P10: /department | AF10: GET | AL10: TKAPI_ListDepartments.xslx
D11: 3 | F11: List certifications | P11: /certification | AF11: GET | AL11: TKAPI_ListCertifications.xslx
D12: 4 | F12: List employees | P12: /employee | AF12: GET | AL12: TKAPI_ListEmployee.xslx

Sheet Ví dụ List QA cần hỏi
A2: STT | B2: Tài liệu | C2: Vùng chức năng | D2: Nohạng mục | E2: Require mô tả | F2: Câu hỏi | G2: Trả lời
A3: 1 | B3: TKMH.xlsx | C3: Chi tiết xử lý | D3: - | E3: - | F3: Trường hợp back về màn hình ADM002 từ các màn hình khác thì có giữ lại paging không? | G3: Có. Back về từ các màn hình ADM003, ADM004, ADM006, system error.
A4: 2 | B4: TKMH.xlsx | C4: Định nghĩa hạng mục | D4: 8 | E4: Dropdown giá trị là danh sách phòng ban Cho phép chọn rỗng (phần tử đầu là rỗng). Nêú user chọn rỗng thì ko search department, ngược lại search theo department id | F4: 1. Giá trị mặc định của hạng mục này là gì? Trong layout Luvina thấy có mô tả là hiển thị text [全て]. Vậy Lu để giá trị mặc định là [全て] nhé? 2. Khi chọn [全て] thì sẽ thực hiện search all theo danh sách phòng ban nhé? | G4: 1. Đúng. Hãy để giá trị mặc định là [全て] 2. Đúng, hãy thực hiện như vậy.
A5: 3 | B5: TKMH.xlsx | C5: Chi tiết xử lý | D5: - | E5: - | F5: Với màn hình ADM0002, có check performance không? Nếu có thì tiêu chuẩn check performance của KH là gì?

Sheet List chức năng
B2: Chức năng chính
C4: Hiển thị màn hình
D5: Vùng header
D6: Vùng danh sách user
E7: Khi load ban đầu
E8: Phân trang
D9: Vùng footer
C10: Action
D11: Search
E12: Gọi API get employee để search thông tin hiển thị lên màn hình
E13: Page hiện tại: 1
D14: Sort | G14: Không test do chưa xử lý
E15: Các cột có sort: 氏名, 日本語能力, 失効日 | G15: Không test do chưa xử lý
E16: Cách sort: Click vào icon ▲▽ để sort tăng dần/giảm dần
D17: Paging
E18: 1 page hiển thị 20 bản ghi
E19: Khi thực hiện search/sort thì paging reset về page 1
E20: Click paging giữ nguyên điều kiện search/sort
D21: Button Add
E22: Di chuyển đến ADM004
D23: Link ID
E24: Di chuyển đến ADM003
